<?xml version="1.0" encoding="utf-8"?>
<!-- This URDF was automatically created by SolidWorks to URDF Exporter! Originally created by Stephen Brawner (brawner@gmail.com) 
     Commit Version: 1.6.0-1-g15f4949  Build Version: 1.6.7594.29634
     For more information, please see http://wiki.ros.org/sw_urdf_exporter -->
<robot
  name="drive">
  <link
    name="base">
    <inertial>
      <origin
        xyz="0.12409 0.20734 1.2"
        rpy="0 0 0" />
      <mass
        value="36.758" />
      <inertia
        ixx="2.1895"
        ixy="-1.7206E-06"
        ixz="0.0047092"
        iyy="2.5602"
        iyz="0.001442"
        izz="0.77249" />
    </inertial>
    <visual>
      <origin
        xyz="0 0 0"
        rpy="0 0 0" />
      <geometry>
        <mesh
          filename="package://drive/meshes/base.STL" />
      </geometry>
      <material
        name="">
        <color
          rgba="0.75294 0.75294 0.75294 1" />
      </material>
    </visual>
    <collision>
      <origin
        xyz="0 0 0"
        rpy="0 0 0" />
      <geometry>
        <mesh
          filename="package://drive/meshes/base.STL" />
      </geometry>
    </collision>
  </link>
  <link
    name="wheel_1">
    <inertial>
      <origin
        xyz="0.109 -0.001534 -0.0094091"
        rpy="0 0 0" />
      <mass
        value="32.802" />
      <inertia
        ixx="0.60349"
        ixy="-0.0034113"
        ixz="-0.020925"
        iyy="0.36113"
        iyz="0.0002962"
        izz="0.3629" />
    </inertial>
    <visual>
      <origin
        xyz="0 0 0"
        rpy="0 0 0" />
      <geometry>
        <mesh
          filename="package://drive/meshes/wheel_1.STL" />
      </geometry>
      <material
        name="">
        <color
          rgba="0.79216 0.81961 0.93333 1" />
      </material>
    </visual>
    <collision>
      <origin
        xyz="0 0 0"
        rpy="0 0 0" />
      <geometry>
        <mesh
          filename="package://drive/meshes/wheel_1.STL" />
      </geometry>
    </collision>
  </link>
  <joint
    name="wheel_joint_1"
    type="continuous">
    <origin
      xyz="-0.12406 -0.94233 0.11392"
      rpy="1.0129 -0.057594 3.076" />
    <parent
      link="base" />
    <child
      link="wheel_1" />
    <axis
      xyz="0.99619 -0.014024 -0.08602" />
  </joint>
  <link
    name="wheel_2">
    <inertial>
      <origin
        xyz="0.109 -0.001534 -0.0094091"
        rpy="0 0 0" />
      <mass
        value="32.802" />
      <inertia
        ixx="0.60349"
        ixy="-0.0034113"
        ixz="-0.020925"
        iyy="0.36113"
        iyz="0.00029621"
        izz="0.3629" />
    </inertial>
    <visual>
      <origin
        xyz="0 0 0"
        rpy="0 0 0" />
      <geometry>
        <mesh
          filename="package://drive/meshes/wheel_2.STL" />
      </geometry>
      <material
        name="">
        <color
          rgba="0.79216 0.81961 0.93333 1" />
      </material>
    </visual>
    <collision>
      <origin
        xyz="0 0 0"
        rpy="0 0 0" />
      <geometry>
        <mesh
          filename="package://drive/meshes/wheel_2.STL" />
      </geometry>
    </collision>
  </link>
  <joint
    name="wheel_joint_2"
    type="continuous">
    <origin
      xyz="0.36212 -0.94269 0.11392"
      rpy="1.71 -0.0019564 -0.087245" />
    <parent
      link="base" />
    <child
      link="wheel_2" />
    <axis
      xyz="0.99619 -0.014024 -0.08602" />
  </joint>
  <link
    name="wheel_3">
    <inertial>
      <origin
        xyz="0.109 -0.001534 -0.0094091"
        rpy="0 0 0" />
      <mass
        value="32.802" />
      <inertia
        ixx="0.60349"
        ixy="-0.0034113"
        ixz="-0.020925"
        iyy="0.36113"
        iyz="0.0002962"
        izz="0.3629" />
    </inertial>
    <visual>
      <origin
        xyz="0 0 0"
        rpy="0 0 0" />
      <geometry>
        <mesh
          filename="package://drive/meshes/wheel_3.STL" />
      </geometry>
      <material
        name="">
        <color
          rgba="0.79216 0.81961 0.93333 1" />
      </material>
    </visual>
    <collision>
      <origin
        xyz="0 0 0"
        rpy="0 0 0" />
      <geometry>
        <mesh
          filename="package://drive/meshes/wheel_3.STL" />
      </geometry>
    </collision>
  </link>
  <joint
    name="wheel_joint_3"
    type="continuous">
    <origin
      xyz="-0.12406 -0.49233 0.11392"
      rpy="0.83798 -0.068122 3.087" />
    <parent
      link="base" />
    <child
      link="wheel_3" />
    <axis
      xyz="0.99619 -0.014024 -0.08602" />
  </joint>
  <link
    name="wheel_4">
    <inertial>
      <origin
        xyz="0.109 -0.001534 -0.0094091"
        rpy="0 0 0" />
      <mass
        value="32.802" />
      <inertia
        ixx="0.60349"
        ixy="-0.0034113"
        ixz="-0.020925"
        iyy="0.36113"
        iyz="0.00029621"
        izz="0.3629" />
    </inertial>
    <visual>
      <origin
        xyz="0 0 0"
        rpy="0 0 0" />
      <geometry>
        <mesh
          filename="package://drive/meshes/wheel_4.STL" />
      </geometry>
      <material
        name="">
        <color
          rgba="0.79216 0.81961 0.93333 1" />
      </material>
    </visual>
    <collision>
      <origin
        xyz="0 0 0"
        rpy="0 0 0" />
      <geometry>
        <mesh
          filename="package://drive/meshes/wheel_4.STL" />
      </geometry>
    </collision>
  </link>
  <joint
    name="wheel_joint_4"
    type="continuous">
    <origin
      xyz="0.36212 -0.49269 0.11392"
      rpy="1.9152 0.015899 -0.08581" />
    <parent
      link="base" />
    <child
      link="wheel_4" />
    <axis
      xyz="0.99619 -0.014024 -0.08602" />
  </joint>
  <link
    name="wheel_5">
    <inertial>
      <origin
        xyz="0.109 -0.001534 -0.0094091"
        rpy="0 0 0" />
      <mass
        value="32.802" />
      <inertia
        ixx="0.60349"
        ixy="-0.0034113"
        ixz="-0.020925"
        iyy="0.36113"
        iyz="0.00029621"
        izz="0.3629" />
    </inertial>
    <visual>
      <origin
        xyz="0 0 0"
        rpy="0 0 0" />
      <geometry>
        <mesh
          filename="package://drive/meshes/wheel_5.STL" />
      </geometry>
      <material
        name="">
        <color
          rgba="0.79216 0.81961 0.93333 1" />
      </material>
    </visual>
    <collision>
      <origin
        xyz="0 0 0"
        rpy="0 0 0" />
      <geometry>
        <mesh
          filename="package://drive/meshes/wheel_5.STL" />
      </geometry>
    </collision>
  </link>
  <joint
    name="wheel_joint_5"
    type="continuous">
    <origin
      xyz="-0.12156 0.11889 0.11392"
      rpy="0.12629 -0.087212 -3.1385" />
    <parent
      link="base" />
    <child
      link="wheel_5" />
    <axis
      xyz="0.99619 -0.014024 -0.08602" />
  </joint>
  <link
    name="wheel_6">
    <inertial>
      <origin
        xyz="0.109 -0.001534 -0.0094091"
        rpy="0 0 0" />
      <mass
        value="32.802" />
      <inertia
        ixx="0.60349"
        ixy="-0.0034113"
        ixz="-0.020925"
        iyy="0.36113"
        iyz="0.0002962"
        izz="0.3629" />
    </inertial>
    <visual>
      <origin
        xyz="0 0 0"
        rpy="0 0 0" />
      <geometry>
        <mesh
          filename="package://drive/meshes/wheel_6.STL" />
      </geometry>
      <material
        name="">
        <color
          rgba="0.79216 0.81961 0.93333 1" />
      </material>
    </visual>
    <collision>
      <origin
        xyz="0 0 0"
        rpy="0 0 0" />
      <geometry>
        <mesh
          filename="package://drive/meshes/wheel_6.STL" />
      </geometry>
    </collision>
  </link>
  <joint
    name="wheel_joint_6"
    type="continuous">
    <origin
      xyz="0.35962 0.11889 0.11392"
      rpy="1.9946 0.022675 -0.084276" />
    <parent
      link="base" />
    <child
      link="wheel_6" />
    <axis
      xyz="0.99619 -0.014024 -0.08602" />
  </joint>
    <!-- Gazebo plugin for ros2_control -->
  <gazebo>
    <plugin filename="ign_ros2_control-system" name="ign_ros2_control::IgnitionROS2ControlPlugin">
      <parameters>$(find drive)/models/drive/config/rover_controllers.yaml</parameters>
      <ros>
        <remapping>/clock:=/clock</remapping>
      </ros>
    </plugin>
  </gazebo>

  <!-- IMU Sensor -->
  <link name="imu_link">
    <inertial>
      <mass value="0.01"/>
      <origin xyz="0 0 0" rpy="0 0 0"/>
      <inertia ixx="1e-5" ixy="0.0" ixz="0.0" iyy="1e-5" iyz="0.0" izz="1e-5"/>
    </inertial>
    <visual>
      <geometry>
        <box size="0.01 0.01 0.01"/>
      </geometry>
    </visual>
    <collision>
      <geometry>
        <box size="0.01 0.01 0.01"/>
      </geometry>
    </collision>
  </link>
  <joint name="imu_joint" type="fixed">
    <parent link="base"/>
    <child link="imu_link"/>
    <origin xyz="0.0 0.0 0.1" rpy="0 0 0"/>
  </joint>
  <gazebo reference="imu_link">
    <sensor name="imu_sensor" type="imu">
      <pose>0 0 0 0 0 0</pose>
      <update_rate>50</update_rate>
      <always_on>true</always_on>
      <visualize>true</visualize>
      <topic>/imu/data</topic>
      <imu>
        <noise>
          <type>gaussian</type>
          <mean>0.0</mean>
          <stddev>0.0002</stddev>
        </noise>
      </imu>
      <plugin filename="libignition-gazebo-imu-system.so"
        name="ignition::gazebo::systems::Imu">
        <topic>/imu</topic>
      </plugin>
    </sensor>
  </gazebo>

<!-- LiDAR Sensor -->
<link name="lidar_link">
    <inertial>
      <mass value="0.01"/>
      <origin xyz="0 0 0" rpy="0 0 0"/>
      <inertia ixx="1e-5" ixy="0.0" ixz="0.0" iyy="1e-5" iyz="0.0" izz="1e-5"/>
    </inertial>
    <visual>
      <geometry>
        <cylinder radius="0.03" length="0.02"/>
      </geometry>
    </visual>
    <collision>
      <geometry>
        <cylinder radius="0.03" length="0.02"/>
      </geometry>
    </collision>
  </link>
  <joint name="lidar_joint" type="fixed">
    <parent link="base"/>
    <child link="lidar_link"/>
    <origin xyz="0.0 0.0 0.15" rpy="0 0 0"/>
  </joint>
  <gazebo reference="lidar_link">
    <sensor name='lidar' type='gpu_lidar'>
      <pose>0 0 0 0 0 0</pose>
      <topic>/scan</topic>
      <update_rate>10</update_rate>
      <ray>
        <scan>
          <horizontal>
            <samples>640</samples>
            <resolution>1</resolution>
            <min_angle>-1.396263</min_angle>
            <max_angle>1.396263</max_angle>
          </horizontal>
          <vertical>
            <samples>1</samples>
            <resolution>0.01</resolution>
            <min_angle>0</min_angle>
            <max_angle>0</max_angle>
          </vertical>
        </scan>
        <range>
          <min>0.08</min>
          <max>10.0</max>
          <resolution>0.01</resolution>
        </range>
      </ray>
      <always_on>1</always_on>
      <visualize>true</visualize>
    </sensor>
  </gazebo>
</robot>



























































































































































































































































































































































































































































































































































































































































































